<?xml version="1.0" encoding="utf-8"?>
<!-- This URDF was automatically created by SolidWorks to URDF Exporter! Originally created by Stephen Brawner (brawner@gmail.com) 
     Commit Version: 1.6.0-1-g15f4949  Build Version: 1.6.7594.29634
     For more information, please see http://wiki.ros.org/sw_urdf_exporter -->
<robot
  name="robot_new">
  <link
    name="base_link">
    <inertial>
      <origin
        xyz="2.87022176508506E-06 -0.00639288068136572 0.00967770424608871"
        rpy="0 0 0" />
      <mass
        value="0.497669657505291" />
      <inertia
        ixx="0.000851783180399219"
        ixy="6.46330143358181E-17"
        ixz="-6.23492759310972E-09"
        iyy="0.000500153741921466"
        iyz="-5.79025605586052E-06"
        izz="0.00129789764708229" />
    </inertial>
    <visual>
      <origin
        xyz="0 0 0"
        rpy="0 0 0" />
      <geometry>
        <mesh
          filename="package://robot_new/meshes/base_link.STL" />
      </geometry>
      <material
        name="">
        <color
          rgba="1 1 1 0.3" />
      </material>
    </visual>
    <collision>
      <origin
        xyz="0 0 0"
        rpy="0 0 0" />
      <geometry>
        <mesh
          filename="package://robot_new/meshes/base_link.STL" />
      </geometry>
    </collision>
  </link>
  <link
    name="wheel_L1_link">
    <inertial>
      <origin
        xyz="-0.0216007758187577 3.75389996865039E-12 -9.22416777210389E-07"
        rpy="0 0 0" />
      <mass
        value="0.042474382918206" />
      <inertia
        ixx="3.57500681796612E-06"
        ixy="-2.95472805667672E-16"
        ixz="1.17807360696107E-10"
        iyy="3.63018537089276E-06"
        iyz="-2.2638403941711E-15"
        izz="3.63034395206029E-06" />
    </inertial>
    <visual>
      <origin
        xyz="0 0 0"
        rpy="0 0 0" />
      <geometry>
        <mesh
          filename="package://robot_new/meshes/wheel_L1_link.STL" />
      </geometry>
      <material
        name="">
        <color
          rgba="0.831372549019608 0.670588235294118 0.129411764705882 1" />
      </material>
    </visual>
    <collision>
      <origin
        xyz="0 0 0"
        rpy="0 0 0" />
      <geometry>
        <mesh
          filename="package://robot_new/meshes/wheel_L1_link.STL" />
      </geometry>
    </collision>
  </link>
  <joint
    name="wheel_L1_link"
    type="continuous">
    <origin
      xyz="-0.066 -0.028021 -0.079221"
      rpy="-1.9687 0 0" />
    <parent
      link="base_link" />
    <child
      link="wheel_L1_link" />
    <axis
      xyz="1 0 0" />
  </joint>
  <link
    name="wheel_L2_link">
    <inertial>
      <origin
        xyz="-0.0216007758188823 -4.42966605458672E-07 -8.09094121395626E-07"
        rpy="0 0 0" />
      <mass
        value="0.0424743829182387" />
      <inertia
        ixx="3.57500681797244E-06"
        ixy="5.65740745429248E-11"
        ixz="1.03334158552787E-10"
        iyy="3.63022194074399E-06"
        iyz="6.67977120597043E-11"
        izz="3.63030738224077E-06" />
    </inertial>
    <visual>
      <origin
        xyz="0 0 0"
        rpy="0 0 0" />
      <geometry>
        <mesh
          filename="package://robot_new/meshes/wheel_L2_link.STL" />
      </geometry>
      <material
        name="">
        <color
          rgba="0.792156862745098 0.819607843137255 0.933333333333333 1" />
      </material>
    </visual>
    <collision>
      <origin
        xyz="0 0 0"
        rpy="0 0 0" />
      <geometry>
        <mesh
          filename="package://robot_new/meshes/wheel_L2_link.STL" />
      </geometry>
    </collision>
  </link>
  <joint
    name="wheel_L2_joint"
    type="continuous">
    <origin
      xyz="-0.066 -0.028021 0.045779"
      rpy="1.6739 0 0" />
    <parent
      link="base_link" />
    <child
      link="wheel_L2_link" />
    <axis
      xyz="1 0 0" />
  </joint>
  <link
    name="wheel_R1_link">
    <inertial>
      <origin
        xyz="-0.0216007759027148 -4.42966605174178E-07 -8.09094120889087E-07"
        rpy="0 0 0" />
      <mass
        value="0.0424743829435536" />
      <inertia
        ixx="3.57500682562334E-06"
        ixy="5.65740745433874E-11"
        ixz="1.03334158552633E-10"
        iyy="3.6302219525341E-06"
        iyz="6.67977120597837E-11"
        izz="3.63030739403088E-06" />
    </inertial>
    <visual>
      <origin
        xyz="0 0 0"
        rpy="0 0 0" />
      <geometry>
        <mesh
          filename="package://robot_new/meshes/wheel_R1_link.STL" />
      </geometry>
      <material
        name="">
        <color
          rgba="0.792156862745098 0.819607843137255 0.933333333333333 1" />
      </material>
    </visual>
    <collision>
      <origin
        xyz="0 0 0"
        rpy="0 0 0" />
      <geometry>
        <mesh
          filename="package://robot_new/meshes/wheel_R1_link.STL" />
      </geometry>
    </collision>
  </link>
  <joint
    name="wheel_R1_link"
    type="continuous">
    <origin
      xyz="0.066 -0.028021 -0.079221"
      rpy="-0.61592 0 3.1416" />
    <parent
      link="base_link" />
    <child
      link="wheel_R1_link" />
    <axis
      xyz="1 0 0" />
  </joint>
  <link
    name="wheel_R2_link">
    <inertial>
      <origin
        xyz="-0.0216007756058552 -4.42966605774392E-07 -8.09094122013188E-07"
        rpy="0 0 0" />
      <mass
        value="0.0424743828860133" />
      <inertia
        ixx="3.57500682962755E-06"
        ixy="5.65740745428516E-11"
        ixz="1.03334158553143E-10"
        iyy="3.63022192320037E-06"
        iyz="6.67977120601013E-11"
        izz="3.63030736469716E-06" />
    </inertial>
    <visual>
      <origin
        xyz="0 0 0"
        rpy="0 0 0" />
      <geometry>
        <mesh
          filename="package://robot_new/meshes/wheel_R2_link.STL" />
      </geometry>
      <material
        name="">
        <color
          rgba="0.792156862745098 0.819607843137255 0.933333333333333 1" />
      </material>
    </visual>
    <collision>
      <origin
        xyz="0 0 0"
        rpy="0 0 0" />
      <geometry>
        <mesh
          filename="package://robot_new/meshes/wheel_R2_link.STL" />
      </geometry>
    </collision>
  </link>
  <joint
    name="wheel_R2_joint"
    type="continuous">
    <origin
      xyz="0.066 -0.028021 0.045779"
      rpy="2.7498 0 3.1416" />
    <parent
      link="base_link" />
    <child
      link="wheel_R2_link" />
    <axis
      xyz="1 0 0" />
  </joint>
  <link
    name="arm_base_link">
    <inertial>
      <origin
        xyz="0.000409242457633803 0.0100004891543178 -0.00064532833159375"
        rpy="0 0 0" />
      <mass
        value="0.0335569271624616" />
      <inertia
        ixx="2.86466699656782E-06"
        ixy="1.44621279598399E-11"
        ixz="4.4862392905134E-08"
        iyy="6.35046586680548E-06"
        iyz="1.32542262641971E-10"
        izz="5.6619535809459E-06" />
    </inertial>
    <visual>
      <origin
        xyz="0 0 0"
        rpy="0 0 0" />
      <geometry>
        <mesh
          filename="package://robot_new/meshes/arm_base_link.STL" />
      </geometry>
      <material
        name="">
        <color
          rgba="0.792156862745098 0.819607843137255 0.933333333333333 1" />
      </material>
    </visual>
    <collision>
      <origin
        xyz="0 0 0"
        rpy="0 0 0" />
      <geometry>
        <mesh
          filename="package://robot_new/meshes/arm_base_link.STL" />
      </geometry>
    </collision>
  </link>
  <joint
    name="arm_base_joint"
    type="fixed">
    <origin
      xyz="-0.0097413 -0.00805 -0.06"
      rpy="1.5708 1.5708 0" />
    <parent
      link="base_link" />
    <child
      link="arm_base_link" />
    <axis
      xyz="0 0 0" />
  </joint>
  <link
    name="arm_link">
    <inertial>
      <origin
        xyz="-7.5764047813287E-16 0.0119191306326669 0"
        rpy="0 0 0" />
      <mass
        value="0.0161811130872279" />
      <inertia
        ixx="3.3532986962083E-06"
        ixy="3.18702305929956E-21"
        ixz="-6.75641124333313E-21"
        iyy="9.34525230106503E-06"
        iyz="8.58840423453778E-22"
        izz="1.11164067282418E-05" />
    </inertial>
    <visual>
      <origin
        xyz="0 0 0"
        rpy="0 0 0" />
      <geometry>
        <mesh
          filename="package://robot_new/meshes/arm_link.STL" />
      </geometry>
      <material
        name="">
        <color
          rgba="0.894117647058823 0.913725490196078 0.929411764705882 1" />
      </material>
    </visual>
    <collision>
      <origin
        xyz="0 0 0"
        rpy="0 0 0" />
      <geometry>
        <mesh
          filename="package://robot_new/meshes/arm_link.STL" />
      </geometry>
    </collision>
  </link>
  <joint
    name="arm_joint"
    type="revolute">
    <origin
      xyz="0.010991 0.01 -0.02715"
      rpy="-1.5708 0 -1.5393" />
    <parent
      link="arm_base_link" />
    <child
      link="arm_link" />
    <axis
      xyz="0 1 0" />
    <limit
      lower="0"
      upper="3.14"
      effort="0"
      velocity="0" />
  </joint>
  <link
    name="arm_link_2">
    <inertial>
      <origin
        xyz="-0.047845528679592 -0.000153782337675032 0.00102202919595453"
        rpy="0 0 0" />
      <mass
        value="0.0909540958388824" />
      <inertia
        ixx="1.49540386290846E-05"
        ixy="-8.45529532700626E-08"
        ixz="5.44667922294372E-15"
        iyy="2.35225072608537E-05"
        iyz="-3.98052124604929E-16"
        izz="1.49935446329835E-05" />
    </inertial>
    <visual>
      <origin
        xyz="0 0 0"
        rpy="0 0 0" />
      <geometry>
        <mesh
          filename="package://robot_new/meshes/arm_link_2.STL" />
      </geometry>
      <material
        name="">
        <color
          rgba="0.792156862745098 0.819607843137255 0.933333333333333 1" />
      </material>
    </visual>
    <collision>
      <origin
        xyz="0 0 0"
        rpy="0 0 0" />
      <geometry>
        <mesh
          filename="package://robot_new/meshes/arm_link_2.STL" />
      </geometry>
    </collision>
  </link>
  <joint
    name="arm_joint_2"
    type="continuous">
    <origin
      xyz="0 0.03 0"
      rpy="-1.5708 0.013773 -1.5708" />
    <parent
      link="arm_link" />
    <child
      link="arm_link_2" />
    <axis
      xyz="0 0 1" />
    <limit
      lower="0"
      upper="3.14"
      effort="0"
      velocity="0" />
  </joint>
  <link
    name="gripper_base_link">
    <inertial>
      <origin
        xyz="3.68191968224893E-08 -0.0164423050943715 0.00137359079403292"
        rpy="0 0 0" />
      <mass
        value="0.0579011557758669" />
      <inertia
        ixx="1.04429253549904E-05"
        ixy="1.50620194739418E-10"
        ixz="1.47707178304849E-11"
        iyy="1.34523506938754E-05"
        iyz="-1.58685694977155E-07"
        izz="1.90358969764955E-05" />
    </inertial>
    <visual>
      <origin
        xyz="0 0 0"
        rpy="0 0 0" />
      <geometry>
        <mesh
          filename="package://robot_new/meshes/gripper_base_link.STL" />
      </geometry>
      <material
        name="">
        <color
          rgba="0.894117647058823 0.913725490196078 0.929411764705882 1" />
      </material>
    </visual>
    <collision>
      <origin
        xyz="0 0 0"
        rpy="0 0 0" />
      <geometry>
        <mesh
          filename="package://robot_new/meshes/gripper_base_link.STL" />
      </geometry>
    </collision>
  </link>
  <joint
    name="gripper_base_joint"
    type="fixed">
    <origin
      xyz="-0.10575 -0.0014342 0"
      rpy="1.6186 -1.5708 0" />
    <parent
      link="arm_link_2" />
    <child
      link="gripper_base_link" />
    <axis
      xyz="0 0 0" />
  </joint>
  <link
    name="gripper_handle_link">
    <inertial>
      <origin
        xyz="1.11862472076951E-06 -4.2727914470464E-07 -0.00233220047683527"
        rpy="0 0 0" />
      <mass
        value="0.000623634723201167" />
      <inertia
        ixx="1.56071870947179E-08"
        ixy="-1.31823523713639E-15"
        ixz="-5.45981322565633E-13"
        iyy="1.56071803442588E-08"
        iyz="-5.82801102072764E-14"
        izz="3.02526102531486E-08" />
    </inertial>
    <visual>
      <origin
        xyz="0 0 0"
        rpy="0 0 0" />
      <geometry>
        <mesh
          filename="package://robot_new/meshes/gripper_handle_link.STL" />
      </geometry>
      <material
        name="">
        <color
          rgba="0.792156862745098 0.819607843137255 0.933333333333333 1" />
      </material>
    </visual>
    <collision>
      <origin
        xyz="0 0 0"
        rpy="0 0 0" />
      <geometry>
        <mesh
          filename="package://robot_new/meshes/gripper_handle_link.STL" />
      </geometry>
    </collision>
  </link>
  <joint
    name="gripper_handle_joint"
    type="revolute">
    <origin
      xyz="0 -0.0379 0.0236"
      rpy="-3.1416 0 2.1394" />
    <parent
      link="gripper_base_link" />
    <child
      link="gripper_handle_link" />
    <axis
      xyz="0 0 1" />
    <limit
      lower="0"
      upper="3.14"
      effort="0"
      velocity="0" />
  </joint>
  <link
    name="gripper_handle_L_link">
    <inertial>
      <origin
        xyz="-4.85722573273506E-15 0.00842034285243953 0.00200000000000517"
        rpy="0 0 0" />
      <mass
        value="0.000742729006421988" />
      <inertia
        ixx="1.19700935013719E-08"
        ixy="-3.89808863665614E-23"
        ixz="-5.78380193933562E-24"
        iyy="5.81202162998421E-08"
        iyz="-1.30280946477102E-23"
        izz="6.8109699117422E-08" />
    </inertial>
    <visual>
      <origin
        xyz="0 0 0"
        rpy="0 0 0" />
      <geometry>
        <mesh
          filename="package://robot_new/meshes/gripper_handle_L_link.STL" />
      </geometry>
      <material
        name="">
        <color
          rgba="0.792156862745098 0.819607843137255 0.933333333333333 1" />
      </material>
    </visual>
    <collision>
      <origin
        xyz="0 0 0"
        rpy="0 0 0" />
      <geometry>
        <mesh
          filename="package://robot_new/meshes/gripper_handle_L_link.STL" />
      </geometry>
    </collision>
  </link>
  <joint
    name="gripper_handle_L_joint"
    type="revolute">
    <origin
      xyz="-0.0063494 0.017867 -0.0081496"
      rpy="0 0 2.2631" />
    <parent
      link="gripper_handle_link" />
    <child
      link="gripper_handle_L_link" />
    <axis
      xyz="0 0 0" />
    <limit
      lower="0"
      upper="3.14"
      effort="0"
      velocity="0" />
  </joint>
  <link
    name="gripper_handle_L2_link">
    <inertial>
      <origin
        xyz="0.00338981962827403 0.00338115283121848 0.0133462468888159"
        rpy="0 0 0" />
      <mass
        value="0.0144466642405174" />
      <inertia
        ixx="1.2504094382989E-06"
        ixy="2.88638553925151E-07"
        ixz="8.14012350999121E-08"
        iyy="3.69756625611567E-06"
        iyz="2.45888791637612E-08"
        izz="3.07872645620185E-06" />
    </inertial>
    <visual>
      <origin
        xyz="0 0 0"
        rpy="0 0 0" />
      <geometry>
        <mesh
          filename="package://robot_new/meshes/gripper_handle_L2_link.STL" />
      </geometry>
      <material
        name="">
        <color
          rgba="0.792156862745098 0.819607843137255 0.933333333333333 1" />
      </material>
    </visual>
    <collision>
      <origin
        xyz="0 0 0"
        rpy="0 0 0" />
      <geometry>
        <mesh
          filename="package://robot_new/meshes/gripper_handle_L2_link.STL" />
      </geometry>
    </collision>
  </link>
  <joint
    name="gripper_handle_L2_link"
    type="revolute">
    <origin
      xyz="0.0098908 0.038092 0.004"
      rpy="0 0 -1.6944" />
    <parent
      link="gripper_handle_L_link" />
    <child
      link="gripper_handle_L2_link" />
    <axis
      xyz="0 0 1" />
    <limit
      lower="0"
      upper="3.14"
      effort="0"
      velocity="0" />
  </joint>
  <link
    name="gripper_handle_R_link">
    <inertial>
      <origin
        xyz="-2.52228793407028E-14 0.00842034285248741 0.00199999999998979"
        rpy="0 0 0" />
      <mass
        value="0.000742729006421985" />
      <inertia
        ixx="1.19700935013717E-08"
        ixy="-1.17744197113248E-19"
        ixz="-2.53349911988507E-22"
        iyy="5.8120216299842E-08"
        iyz="-2.3843481156841E-22"
        izz="6.81096991174218E-08" />
    </inertial>
    <visual>
      <origin
        xyz="0 0 0"
        rpy="0 0 0" />
      <geometry>
        <mesh
          filename="package://robot_new/meshes/gripper_handle_R_link.STL" />
      </geometry>
      <material
        name="">
        <color
          rgba="0.792156862745098 0.819607843137255 0.933333333333333 1" />
      </material>
    </visual>
    <collision>
      <origin
        xyz="0 0 0"
        rpy="0 0 0" />
      <geometry>
        <mesh
          filename="package://robot_new/meshes/gripper_handle_R_link.STL" />
      </geometry>
    </collision>
  </link>
  <joint
    name="gripper_handle_R_joint"
    type="revolute">
    <origin
      xyz="0.0068923 -0.017528 -0.0041496"
      rpy="3.1416 0 2.3138" />
    <parent
      link="gripper_handle_link" />
    <child
      link="gripper_handle_R_link" />
    <axis
      xyz="0 0 0" />
    <limit
      lower="0"
      upper="3.14"
      effort="0"
      velocity="0" />
  </joint>
  <link
    name="gripper_handle_R2_link">
    <inertial>
      <origin
        xyz="0.00340716109696093 0.00337589503360927 0.0136585678713081"
        rpy="0 0 0" />
      <mass
        value="0.0144691642405174" />
      <inertia
        ixx="1.25166959776754E-06"
        ixy="2.89485621888409E-07"
        ixz="-8.21769266099686E-08"
        iyy="3.7001760402048E-06"
        iyz="-2.4353695562435E-08"
        izz="3.08208972958961E-06" />
    </inertial>
    <visual>
      <origin
        xyz="0 0 0"
        rpy="0 0 0" />
      <geometry>
        <mesh
          filename="package://robot_new/meshes/gripper_handle_R2_link.STL" />
      </geometry>
      <material
        name="">
        <color
          rgba="0.792156862745098 0.819607843137255 0.933333333333333 1" />
      </material>
    </visual>
    <collision>
      <origin
        xyz="0 0 0"
        rpy="0 0 0" />
      <geometry>
        <mesh
          filename="package://robot_new/meshes/gripper_handle_R2_link.STL" />
      </geometry>
    </collision>
  </link>
  <joint
    name="gripper_handle_R2_joint"
    type="revolute">
    <origin
      xyz="0.00059329 -0.031747 -0.027"
      rpy="0 0 1.7452" />
    <parent
      link="gripper_handle_R_link" />
    <child
      link="gripper_handle_R2_link" />
    <axis
      xyz="0 0 -1" />
    <limit
      lower="0"
      upper="3.14"
      effort="0"
      velocity="0" />
  </joint>
  <link
    name="camera_link">
    <inertial>
      <origin
        xyz="-0.00186319094565714 -0.000148917381217112 -0.00257399330896596"
        rpy="0 0 0" />
      <mass
        value="0.0044910612915397" />
      <inertia
        ixx="3.47246489196688E-07"
        ixy="-2.92050362478453E-10"
        ixz="-2.10429943922637E-09"
        iyy="6.18158335014519E-07"
        iyz="-9.34674831291002E-11"
        izz="2.88843269142911E-07" />
    </inertial>
    <visual>
      <origin
        xyz="0 0 0"
        rpy="0 0 0" />
      <geometry>
        <mesh
          filename="package://robot_new/meshes/camera_link.STL" />
      </geometry>
      <material
        name="">
        <color
          rgba="0.792156862745098 0.819607843137255 0.933333333333333 1" />
      </material>
    </visual>
    <collision>
      <origin
        xyz="0 0 0"
        rpy="0 0 0" />
      <geometry>
        <mesh
          filename="package://robot_new/meshes/camera_link.STL" />
      </geometry>
    </collision>
  </link>
  <joint
    name="camera_joint"
    type="fixed">
    <origin
      xyz="0 -0.016834 0.051"
      rpy="3.1416 0 0" />
    <parent
      link="gripper_base_link" />
    <child
      link="camera_link" />
    <axis
      xyz="0 0 0" />
  </joint>
</robot>